Workbook

Sheet Car & LME
A1: Serial | B1: Deal . No | C1: Name | D1: Rim . No | E1: Branch | F1: Loan Account | G1: Amount | H1: Booking Date | I1: Clean/Secured
C2: CAR
A4: 150859 | B4: 1767986 | C4: ممدوح احمد مصطفى احمد | D4: 2344239 | E4: Hassan El Maamoun Branch | F4: 600000638562 | G4: 900000 | H4: 31/08/2026 | I4: =IF(AND(ISERROR(SEARCH("unsecured",J4)),ISERROR(SEARCH("non secured",J4)),OR(ISNUMBER(SEARCH("Fully S",J4)),ISNUMBER(SEARCH("Secured",J4)))),"Fully Secured","Clean") -> Clean
A5: 150860 | B5: 1767122 | C5: منال مكرم عبيد ميخائيل | D5: 2356503 | E5: Heliopolis Meriland | F5: 600000638419 | G5: 709500 | H5: 31/08/2026 | I5: =IF(AND(ISERROR(SEARCH("unsecured",J5)),ISERROR(SEARCH("non secured",J5)),OR(ISNUMBER(SEARCH("Fully S",J5)),ISNUMBER(SEARCH("Secured",J5)))),"Fully Secured","Clean") -> Clean
A6: 150861 | B6: 1764817 | C6: منه الله محمود حسانين ابراهيم ابوالعنين | D6: 2384323 | E6: Heliopolis Meriland | F6: 600000638425 | G6: 630000 | H6: 31/08/2026 | I6: =IF(AND(ISERROR(SEARCH("unsecured",J6)),ISERROR(SEARCH("non secured",J6)),OR(ISNUMBER(SEARCH("Fully S",J6)),ISNUMBER(SEARCH("Secured",J6)))),"Fully Secured","Clean") -> Clean
A7: 150862 | B7: 1763382 | C7: ميرهان صابر حمدى ابراهيم | D7: 2382093 | E7: Heliopolis Meriland | F7: 600000638323 | G7: 600000 | H7: 31/08/2026 | I7: =IF(AND(ISERROR(SEARCH("unsecured",J7)),ISERROR(SEARCH("non secured",J7)),OR(ISNUMBER(SEARCH("Fully S",J7)),ISNUMBER(SEARCH("Secured",J7)))),"Fully Secured","Clean") -> Clean
A8: 150863 | B8: 1769713 | C8: ناصر محمد السيد حفنى | D8: 2378783 | E8: 6 th October | F8: 600000638332 | G8: 1125000 | H8: 31/08/2026 | I8: =IF(AND(ISERROR(SEARCH("unsecured",J8)),ISERROR(SEARCH("non secured",J8)),OR(ISNUMBER(SEARCH("Fully S",J8)),ISNUMBER(SEARCH("Secured",J8)))),"Fully Secured","Clean") -> Clean
A9: 150864 | B9: 1763487 | C9: نبيل نصحى رزق جرجس | D9: 2357217 | E9: Shoubra Branch | F9: 600000638726 | G9: 1399500 | H9: 31/08/2026 | I9: =IF(AND(ISERROR(SEARCH("unsecured",J9)),ISERROR(SEARCH("non secured",J9)),OR(ISNUMBER(SEARCH("Fully S",J9)),ISNUMBER(SEARCH("Secured",J9)))),"Fully Secured","Clean") -> Clean
A10: 150865 | B10: 1771759 | C10: نجلاء رضا حافظ محمد السعدنى | D10: 2364608 | E10: Heliopolis Meriland | F10: 600000638652 | G10: 450000 | H10: 31/08/2026 | I10: =IF(AND(ISERROR(SEARCH("unsecured",J10)),ISERROR(SEARCH("non secured",J10)),OR(ISNUMBER(SEARCH("Fully S",J10)),ISNUMBER(SEARCH("Secured",J10)))),"Fully Secured","Clean") -> Clean
A11: 150866 | B11: 1765575 | C11: نسيم محمود محمد حسن حرز | D11: 2285133 | E11: Faraskour | F11: 600000638572 | G11: 1704000 | H11: 31/08/2026 | I11: =IF(AND(ISERROR(SEARCH("unsecured",J11)),ISERROR(SEARCH("non secured",J11)),OR(ISNUMBER(SEARCH("Fully S",J11)),ISNUMBER(SEARCH("Secured",J11)))),"Fully Secured","Clean") -> Clean
A12: 150867 | B12: 1768724 | C12: نهال محمد كمال عمر زريق | D12: 2390071 | E12: Heliopolis Meriland | F12: 600000638519 | G12: 205000 | H12: 31/08/2026 | I12: =IF(AND(ISERROR(SEARCH("unsecured",J12)),ISERROR(SEARCH("non secured",J12)),OR(ISNUMBER(SEARCH("Fully S",J12)),ISNUMBER(SEARCH("Secured",J12)))),"Fully Secured","Clean") -> Clean
A13: 150868 | B13: 1772254 | C13: نوره محمد جباره عمر حامد | D13: 2364533 | E13: Mall Of Egypt | F13: 600000638418 | G13: 360000 | H13: 31/08/2026 | I13: =IF(AND(ISERROR(SEARCH("unsecured",J13)),ISERROR(SEARCH("non secured",J13)),OR(ISNUMBER(SEARCH("Fully S",J13)),ISNUMBER(SEARCH("Secured",J13)))),"Fully Secured","Clean") -> Clean
A14: 150869 | B14: 1769912 | C14: هاجر مجدى محمد عبدالمجيد | D14: 2391398 | E14: Heliopolis Meriland | F14: 600000638458 | G14: 647000 | H14: 31/08/2026 | I14: =IF(AND(ISERROR(SEARCH("unsecured",J14)),ISERROR(SEARCH("non secured",J14)),OR(ISNUMBER(SEARCH("Fully S",J14)),ISNUMBER(SEARCH("Secured",J14)))),"Fully Secured","Clean") -> Clean
A15: 150870 | B15: 1768499 | C15: هايدى خالد ناجى عبدالعزيز | D15: 1689056 | E15: Dokki | F15: 600000638423 | G15: 387500 | H15: 31/08/2026 | I15: =IF(AND(ISERROR(SEARCH("unsecured",J15)),ISERROR(SEARCH("non secured",J15)),OR(ISNUMBER(SEARCH("Fully S",J15)),ISNUMBER(SEARCH("Secured",J15)))),"Fully Secured","Clean") -> Clean
... A31: 150886 | B31: 1760166 | C31: ياسر محمد زكريا عبدالعزيز | D31: 2377871 | E31: October Plaza | F31: 600000638327 | G31: 627500 | H31: 31/08/2026 | I31: =IF(AND(ISERROR(SEARCH("unsecured",J31)),ISERROR(SEARCH("non secured",J31)),OR(ISNUMBER(SEARCH("Fully S",J31)),ISNUMBER(SEARCH("Secured",J31)))),"Fully Secured","Clean") -> Clean
C35: LME
A36: 177163 | B36: 1765353 | C36: مروة محمود ياسين محمود نيو رويال سمايل | D36: 2384856 | E36: Garden City | F36: 600000638798 | G36: 2300000 | H36: 31/08/2026 | I36: =IF(AND(ISERROR(SEARCH("unsecured",J36)),ISERROR(SEARCH("non secured",J36)),OR(ISNUMBER(SEARCH("Fully S",J36)),ISNUMBER(SEARCH("Secured",J36)))),"Fully Secured","Clean") -> Clean
A37: 177164 | B37: 1770191 | C37: مصطفى ابراهيم حسن ابراهيم | D37: 1908116 | E37: Garden City | F37: 600000638660 | G37: 200000 | H37: 31/08/2026 | I37: =IF(AND(ISERROR(SEARCH("unsecured",J37)),ISERROR(SEARCH("non secured",J37)),OR(ISNUMBER(SEARCH("Fully S",J37)),ISNUMBER(SEARCH("Secured",J37)))),"Fully Secured","Clean") -> Clean
A38: 177165 | B38: 1770646 | C38: مصطفى أنور احمد محمد الفقى ام & ان دنتال كلينيك | D38: 1763711 | E38: Zahraa El Maadi | F38: 600000638667 | G38: 1130000 | H38: 31/08/2026 | I38: =IF(AND(ISERROR(SEARCH("unsecured",J38)),ISERROR(SEARCH("non secured",J38)),OR(ISNUMBER(SEARCH("Fully S",J38)),ISNUMBER(SEARCH("Secured",J38)))),"Fully Secured","Clean") -> Clean
A39: 177166 | B39: 1773320 | C39: مصطفى عبدربه خلف عبدربه | D39: 1438194 | E39: Sohag | F39: 600000638751 | G39: 30000 | H39: 31/08/2026 | I39: =IF(AND(ISERROR(SEARCH("unsecured",J39)),ISERROR(SEARCH("non secured",J39)),OR(ISNUMBER(SEARCH("Fully S",J39)),ISNUMBER(SEARCH("Secured",J39)))),"Fully Secured","Clean") -> Clean
A40: 177167 | B40: 1769202 | C40: مصطفي فاروق حسين ابراهيم عيادة د مصطفى فاروق حسين | D40: 1895593 | E40: Garden City | F40: 600000638755 | G40: 669000 | H40: 31/08/2026 | I40: =IF(AND(ISERROR(SEARCH("unsecured",J40)),ISERROR(SEARCH("non secured",J40)),OR(ISNUMBER(SEARCH("Fully S",J40)),ISNUMBER(SEARCH("Secured",J40)))),"Fully Secured","Clean") -> Clean
A41: 177168 | B41: 1773208 | C41: معتز محمد محمد سليمان الجوهرى | D41: 2377283 | E41: Mostafa ElNahas | F41: 600000638399 | G41: 250000 | H41: 31/08/2026 | I41: =IF(AND(ISERROR(SEARCH("unsecured",J41)),ISERROR(SEARCH("non secured",J41)),OR(ISNUMBER(SEARCH("Fully S",J41)),ISNUMBER(SEARCH("Secured",J41)))),"Fully Secured","Clean") -> Clean
A42: 177169 | B42: 1767842 | C42: ممدوح حسين حسن اسماعيل | D42: 1140679 | E42: Dokki | F42: 600000638651 | G42: 550000 | H42: 31/08/2026 | I42: =IF(AND(ISERROR(SEARCH("unsecured",J42)),ISERROR(SEARCH("non secured",J42)),OR(ISNUMBER(SEARCH("Fully S",J42)),ISNUMBER(SEARCH("Secured",J42)))),"Fully Secured","Clean") -> Clean
A43: 177170 | B43: 1764642 | C43: ناير نشأت سامى جورجى | D43: 2384239 | E43: Garden City | F43: 600000638777 | G43: 950000 | H43: 31/08/2026 | I43: =IF(AND(ISERROR(SEARCH("unsecured",J43)),ISERROR(SEARCH("non secured",J43)),OR(ISNUMBER(SEARCH("Fully S",J43)),ISNUMBER(SEARCH("Secured",J43)))),"Fully Secured","Clean") -> Clean
A44: 177171 | B44: 1774086 | C44: نجلاء فتحى حسين عبدالنبى | D44: 2368536 | E44: El Borsa | F44: 600000638780 | G44: 244000 | H44: 31/08/2026 | I44: =IF(AND(ISERROR(SEARCH("unsecured",J44)),ISERROR(SEARCH("non secured",J44)),OR(ISNUMBER(SEARCH("Fully S",J44)),ISNUMBER(SEARCH("Secured",J44)))),"Fully Secured","Clean") -> Clean
A45: 177172 | B45: 1765186 | C45: ندى وسيم منصور يوسف | D45: 2358577 | E45: El Borsa | F45: 600000638748 | G45: 100000 | H45: 31/08/2026 | I45: =IF(AND(ISERROR(SEARCH("unsecured",J45)),ISERROR(SEARCH("non secured",J45)),OR(ISNUMBER(SEARCH("Fully S",J45)),ISNUMBER(SEARCH("Secured",J45)))),"Fully Secured","Clean") -> Clean
A46: 177173 | B46: 1765995 | C46: نور محمد ناجى عبدالحفيظ | D46: 1642475 | E46: Dokki | F46: 600000638658 | G46: 708000 | H46: 31/08/2026 | I46: =IF(AND(ISERROR(SEARCH("unsecured",J46)),ISERROR(SEARCH("non secured",J46)),OR(ISNUMBER(SEARCH("Fully S",J46)),ISNUMBER(SEARCH("Secured",J46)))),"Fully Secured","Clean") -> Clean
A47: 177174 | B47: 1757807 | C47: نوره محمد عبدالحكيم عبداللاه عطوه | D47: 2374727 | E47: Garden City | F47: 600000638545 | G47: 530000 | H47: 31/08/2026 | I47: =IF(AND(ISERROR(SEARCH("unsecured",J47)),ISERROR(SEARCH("non secured",J47)),OR(ISNUMBER(SEARCH("Fully S",J47)),ISNUMBER(SEARCH("Secured",J47)))),"Fully Secured","Clean") -> Clean
... A61: 177188 | B61: 1767277 | C61: يوسف السيد ابراهيم منصور | D61: 1832281 | E61: Garden City | F61: 600000638801 | G61: 1000000 | H61: 31/08/2026 | I61: =IF(AND(ISERROR(SEARCH("unsecured",J61)),ISERROR(SEARCH("non secured",J61)),OR(ISNUMBER(SEARCH("Fully S",J61)),ISNUMBER(SEARCH("Secured",J61)))),"Fully Secured","Clean") -> Clean

Sheet Settle
A1: Serial | B1: Name | C1: Deal . No | D1: Rim . No | E1: Branch | F1: Product | G1: Box Number
C2: Filling release letter and clearance letters | G2: Box 2216
A3: 272057 | B3: =VLOOKUP(C3,'Car & LME'!B:C,2,0) -> #N/A | C3: 856848 | D3: =VLOOKUP(C3,'Car & LME'!B:D,3,0) -> #N/A | E3: =VLOOKUP(C3,'Car & LME'!B:E,4,0) -> #N/A | F3: LME | G3: Box 2217
A4: 272058 | B4: =VLOOKUP(C4,'Car & LME'!B:C,2,0) -> #N/A | C4: 858359 | D4: =VLOOKUP(C4,'Car & LME'!B:D,3,0) -> #N/A | E4: =VLOOKUP(C4,'Car & LME'!B:E,4,0) -> #N/A | F4: LME | G4: Box 2217
A5: 272059 | B5: =VLOOKUP(C5,'Car & LME'!B:C,2,0) -> #N/A | C5: 856217 | D5: =VLOOKUP(C5,'Car & LME'!B:D,3,0) -> #N/A | E5: =VLOOKUP(C5,'Car & LME'!B:E,4,0) -> #N/A | F5: LME | G5: Box 2217
A6: 272060 | B6: =VLOOKUP(C6,'Car & LME'!B:C,2,0) -> #N/A | C6: 855914 | D6: =VLOOKUP(C6,'Car & LME'!B:D,3,0) -> #N/A | E6: =VLOOKUP(C6,'Car & LME'!B:E,4,0) -> #N/A | F6: LME | G6: Box 2217
A7: 272061 | B7: =VLOOKUP(C7,'Car & LME'!B:C,2,0) -> #N/A | C7: 853538 | D7: =VLOOKUP(C7,'Car & LME'!B:D,3,0) -> #N/A | E7: =VLOOKUP(C7,'Car & LME'!B:E,4,0) -> #N/A | F7: LME | G7: Box 2217
A8: 272062 | B8: =VLOOKUP(C8,'Car & LME'!B:C,2,0) -> #N/A | C8: 851589 | D8: =VLOOKUP(C8,'Car & LME'!B:D,3,0) -> #N/A | E8: =VLOOKUP(C8,'Car & LME'!B:E,4,0) -> #N/A | F8: LME | G8: Box 2217
A9: 272063 | B9: =VLOOKUP(C9,'Car & LME'!B:C,2,0) -> #N/A | C9: 974601 | D9: =VLOOKUP(C9,'Car & LME'!B:D,3,0) -> #N/A | E9: =VLOOKUP(C9,'Car & LME'!B:E,4,0) -> #N/A | F9: LME | G9: Box 2217
A10: 272064 | B10: =VLOOKUP(C10,'Car & LME'!B:C,2,0) -> #N/A | C10: 975402 | D10: =VLOOKUP(C10,'Car & LME'!B:D,3,0) -> #N/A | E10: =VLOOKUP(C10,'Car & LME'!B:E,4,0) -> #N/A | F10: LME | G10: Box 2217
A11: 272065 | B11: =VLOOKUP(C11,'Car & LME'!B:C,2,0) -> #N/A | C11: 1074428 | D11: =VLOOKUP(C11,'Car & LME'!B:D,3,0) -> #N/A | E11: =VLOOKUP(C11,'Car & LME'!B:E,4,0) -> #N/A | F11: LME | G11: Box 2217
A12: 272066 | B12: =VLOOKUP(C12,'Car & LME'!B:C,2,0) -> #N/A | C12: 1077500 | D12: =VLOOKUP(C12,'Car & LME'!B:D,3,0) -> #N/A | E12: =VLOOKUP(C12,'Car & LME'!B:E,4,0) -> #N/A | F12: LME | G12: Box 2217
A13: 272067 | B13: =VLOOKUP(C13,'Car & LME'!B:C,2,0) -> #N/A | C13: 1073404 | D13: =VLOOKUP(C13,'Car & LME'!B:D,3,0) -> #N/A | E13: =VLOOKUP(C13,'Car & LME'!B:E,4,0) -> #N/A | F13: LME | G13: Box 2217
A14: 272068 | B14: =VLOOKUP(C14,'Car & LME'!B:C,2,0) -> #N/A | C14: 1079874 | D14: =VLOOKUP(C14,'Car & LME'!B:D,3,0) -> #N/A | E14: =VLOOKUP(C14,'Car & LME'!B:E,4,0) -> #N/A | F14: LME | G14: Box 2217
... A1112: 273166 | B1112: =VLOOKUP(C1112,'Car & LME'!B:C,2,0) -> #N/A | C1112: 852066 | D1112: =VLOOKUP(C1112,'Car & LME'!B:D,3,0) -> #N/A | E1112: =VLOOKUP(C1112,'Car & LME'!B:E,4,0) -> #N/A | F1112: CAR | G1112: Box 2223
A1113: 273167 | B1113: =VLOOKUP(C1113,'Car & LME'!B:C,2,0) -> #N/A | C1113: 857270 | D1113: =D1115 -> #N/A | E1113: =VLOOKUP(C1113,'Car & LME'!B:E,4,0) -> #N/A | F1113: CAR | G1113: Box 2223
A1114: 273168 | B1114: =VLOOKUP(C1114,'Car & LME'!B:C,2,0) -> #N/A | C1114: 1253399 | D1114: =VLOOKUP(C1114,'Car & LME'!B:D,3,0) -> #N/A | E1114: =VLOOKUP(C1114,'Car & LME'!B:E,4,0) -> #N/A | F1114: CAR | G1114: Box 2223
A1115: 273169 | B1115: =VLOOKUP(C1115,'Car & LME'!B:C,2,0) -> #N/A | C1115: 1252383 | D1115: =VLOOKUP(C1115,'Car & LME'!B:D,3,0) -> #N/A | E1115: =VLOOKUP(C1115,'Car & LME'!B:E,4,0) -> #N/A | F1115: CAR | G1115: Box 2223
A1116: 273170 | B1116: =VLOOKUP(C1116,'Car & LME'!B:C,2,0) -> #N/A | C1116: 1239412 | D1116: =VLOOKUP(C1116,'Car & LME'!B:D,3,0) -> #N/A | E1116: =VLOOKUP(C1116,'Car & LME'!B:E,4,0) -> #N/A | F1116: CAR | G1116: Box 2223
A1117: 273171 | B1117: =VLOOKUP(C1117,'Car & LME'!B:C,2,0) -> #N/A | C1117: 1184699 | D1117: =VLOOKUP(C1117,'Car & LME'!B:D,3,0) -> #N/A | E1117: =VLOOKUP(C1117,'Car & LME'!B:E,4,0) -> #N/A | F1117: CAR | G1117: Box 2223
A1118: 273172 | B1118: =VLOOKUP(C1118,'Car & LME'!B:C,2,0) -> #N/A | C1118: 1104880 | D1118: =VLOOKUP(C1118,'Car & LME'!B:D,3,0) -> #N/A | E1118: =VLOOKUP(C1118,'Car & LME'!B:E,4,0) -> #N/A | F1118: CAR | G1118: Box 2223
A1119: 273173 | B1119: =VLOOKUP(C1119,'Car & LME'!B:C,2,0) -> #N/A | C1119: 1087902 | D1119: =VLOOKUP(C1119,'Car & LME'!B:D,3,0) -> #N/A | E1119: =VLOOKUP(C1119,'Car & LME'!B:E,4,0) -> #N/A | F1119: CAR | G1119: Box 2223
A1120: 273174 | B1120: =VLOOKUP(C1120,'Car & LME'!B:C,2,0) -> #N/A | C1120: 1077117 | D1120: =VLOOKUP(C1120,'Car & LME'!B:D,3,0) -> #N/A | E1120: =VLOOKUP(C1120,'Car & LME'!B:E,4,0) -> #N/A | F1120: CAR | G1120: Box 2223
A1121: 273175 | B1121: =VLOOKUP(C1121,'Car & LME'!B:C,2,0) -> #N/A | C1121: 1062343 | D1121: =VLOOKUP(C1121,'Car & LME'!B:D,3,0) -> #N/A | E1121: =VLOOKUP(C1121,'Car & LME'!B:E,4,0) -> #N/A | F1121: CAR | G1121: Box 2223
A1122: 273176 | B1122: =VLOOKUP(C1122,'Car & LME'!B:C,2,0) -> #N/A | C1122: 1003789 | D1122: =VLOOKUP(C1122,'Car & LME'!B:D,3,0) -> #N/A | E1122: =VLOOKUP(C1122,'Car & LME'!B:E,4,0) -> #N/A | F1122: CAR | G1122: Box 2223
A1123: 273177 | B1123: =VLOOKUP(C1123,'Car & LME'!B:C,2,0) -> #N/A | C1123: 984754 | D1123: =VLOOKUP(C1123,'Car & LME'!B:D,3,0) -> #N/A | E1123: =VLOOKUP(C1123,'Car & LME'!B:E,4,0) -> #N/A | F1123: CAR | G1123: Box 2223
A1124: 273178 | B1124: =VLOOKUP(C1124,'Car & LME'!B:C,2,0) -> #N/A | C1124: 978908 | D1124: =VLOOKUP(C1124,'Car & LME'!B:D,3,0) -> #N/A | E1124: =VLOOKUP(C1124,'Car & LME'!B:E,4,0) -> #N/A | F1124: CAR | G1124: Box 2223
A1125: 273179 | B1125: =VLOOKUP(C1125,'Car & LME'!B:C,2,0) -> #N/A | C1125: 888455 | D1125: =VLOOKUP(C1125,'Car & LME'!B:D,3,0) -> #N/A | E1125: =VLOOKUP(C1125,'Car & LME'!B:E,4,0) -> #N/A | F1125: CAR | G1125: Box 2223
... A1742: 273796 | B1742: =VLOOKUP(C1742,'Car & LME'!B:C,2,0) -> #N/A | C1742: 1626867 | D1742: =VLOOKUP(C1742,'Car & LME'!B:D,3,0) -> #N/A | E1742: =VLOOKUP(C1742,'Car & LME'!B:E,4,0) -> #N/A | F1742: LME | G1742: Box 2227
A1743: 273797 | B1743: احمد محمد محمد جابر موسى | C1743: 1719056 | D1743: 2327552 | E1743: Heliopolis Meriland | F1743: CAR | G1743: Box 2227
A1744: 273798 | B1744: =VLOOKUP(C1744,'Car & LME'!B:C,2,0) -> #N/A | C1744: 1050457 | D1744: =VLOOKUP(C1744,'Car & LME'!B:D,3,0) -> #N/A | E1744: =VLOOKUP(C1744,'Car & LME'!B:E,4,0) -> #N/A | F1744: LME | G1744: Box 2227
A1745: 273799 | B1745: =VLOOKUP(C1745,'Car & LME'!B:C,2,0) -> #N/A | C1745: 1579447 | D1745: =VLOOKUP(C1745,'Car & LME'!B:D,3,0) -> #N/A | E1745: =VLOOKUP(C1745,'Car & LME'!B:E,4,0) -> #N/A | F1745: LME | G1745: Box 2227
A1746: 273800 | B1746: =VLOOKUP(C1746,'Car & LME'!B:C,2,0) -> #N/A | C1746: 1614574 | D1746: =VLOOKUP(C1746,'Car & LME'!B:D,3,0) -> #N/A | E1746: =VLOOKUP(C1746,'Car & LME'!B:E,4,0) -> #N/A | F1746: LME | G1746: Box 2227
A1747: 273801 | B1747: =VLOOKUP(C1747,'Car & LME'!B:C,2,0) -> #N/A | C1747: 1483513 | D1747: =VLOOKUP(C1747,'Car & LME'!B:D,3,0) -> #N/A | E1747: =VLOOKUP(C1747,'Car & LME'!B:E,4,0) -> #N/A | F1747: LME | G1747: Box 2227
A1748: 273802 | B1748: =VLOOKUP(C1748,'Car & LME'!B:C,2,0) -> #N/A | C1748: 1335722 | D1748: =VLOOKUP(C1748,'Car & LME'!B:D,3,0) -> #N/A | E1748: =VLOOKUP(C1748,'Car & LME'!B:E,4,0) -> #N/A | F1748: LME | G1748: Box 2227
A1749: 273803 | B1749: =VLOOKUP(C1749,'Car & LME'!B:C,2,0) -> #N/A | C1749: 1297946 | D1749: =VLOOKUP(C1749,'Car & LME'!B:D,3,0) -> #N/A | E1749: =VLOOKUP(C1749,'Car & LME'!B:E,4,0) -> #N/A | F1749: LME | G1749: Box 2227
A1750: 273804 | B1750: =VLOOKUP(C1750,'Car & LME'!B:C,2,0) -> #N/A | C1750: 1288837 | D1750: =VLOOKUP(C1750,'Car & LME'!B:D,3,0) -> #N/A | E1750: =VLOOKUP(C1750,'Car & LME'!B:E,4,0) -> #N/A | F1750: LME | G1750: Box 2227
A1751: 273805 | B1751: =VLOOKUP(C1751,'Car & LME'!B:C,2,0) -> #N/A | C1751: 1253938 | D1751: =VLOOKUP(C1751,'Car & LME'!B:D,3,0) -> #N/A | E1751: =VLOOKUP(C1751,'Car & LME'!B:E,4,0) -> #N/A | F1751: LME | G1751: Box 2227
A1752: 273806 | B1752: =VLOOKUP(C1752,'Car & LME'!B:C,2,0) -> #N/A | C1752: 1254014 | D1752: =VLOOKUP(C1752,'Car & LME'!B:D,3,0) -> #N/A | E1752: =VLOOKUP(C1752,'Car & LME'!B:E,4,0) -> #N/A | F1752: LME | G1752: Box 2227
A1753: 273807 | B1753: =VLOOKUP(C1753,'Car & LME'!B:C,2,0) -> #N/A | C1753: 1113316 | D1753: =VLOOKUP(C1753,'Car & LME'!B:D,3,0) -> #N/A | E1753: =VLOOKUP(C1753,'Car & LME'!B:E,4,0) -> #N/A | F1753: LME | G1753: Box 2227
...
